Workbook

Sheet Posts
A1: PostID | B1: Platform | C1: Date | D1: ContentType | E1: Hashtags | F1: Likes | G1: Shares | H1: Comments | I1: Clicks | J1: Reach | K1: Impressions | L1: Campaign
A2: A1 | B2: YouTube | C2: 45649 | D2: Image | E2: #AppleWatchUltra2 #HealthTech | F2: 24516 | G2: 976 | H2: 974 | I2: 2675 | J2: 23275 | K2: 202932 | L2: Apple Watch Ultra 2 Launch
A3: A2 | B3: LinkedIn | C3: 45903 | D3: Image | E3: #MacBookAirM3 #AppleInnovation | F3: 4779 | G3: 1110 | H3: 436 | I3: 1574 | J3: 77167 | K3: 71585 | L3: Apple Event September 2025
A4: A3 | B4: Instagram | C4: 45789 | D4: Tweet | E4: #AppleDesign #Innovation | F4: 19308 | G4: 1318 | H4: 795 | I4: 1499 | J4: 52307 | K4: 193087 | L4: Sustainability Awareness Drive
A5: A4 | B5: YouTube | C5: 45516 | D5: Video | E5: #AppleEvent #iPadPro | F5: 3581 | G5: 517 | H5: 880 | I5: 1925 | J5: 18636 | K5: 248611 | L5: iPhone 16 Launch
A6: A5 | B6: YouTube | C6: 45904 | D6: Video | E6: #AppleWatchUltra2 #HealthTech | F6: 21708 | G6: 435 | H6: 317 | I6: 1213 | J6: 70701 | K6: 83585 | L6: Apple Event September 2025
A7: A6 | B7: LinkedIn | C7: 45905 | D7: Image | E7: #ShotOniPhone | F7: 14677 | G7: 533 | H7: 759 | I7: 753 | J7: 23275 | K7: 66958 | L7: Apple Event September 2025
A8: A7 | B8: Instagram | C8: 45467 | D8: Carousel | E8: #AppleMusic #AppleLifestyle | F8: 7713 | G8: 575 | H8: 417 | I8: 336 | J8: 61660 | K8: 66017 | L8: iPhone 16 Launch
A9: A8 | B9: Instagram | C9: 45486 | D9: Video | E9: #AppleWatch #Health | F9: 18639 | G9: 1360 | H9: 898 | I9: 2011 | J9: 42841 | K9: 247779 | L9: iPhone 16 Launch
A10: A9 | B10: YouTube | C10: 45534 | D10: Carousel | E10: #MacBookAirM3 #AppleInnovation | F10: 6804 | G10: 787 | H10: 970 | I10: 1095 | J10: 56343 | K10: 164677 | L10: Apple Watch Ultra 2 Launch
A11: A10 | B11: Twitter | C11: 45727 | D11: Video | E11: #iPhone16Launch #AppleEvent | F11: 20222 | G11: 712 | H11: 604 | I11: 1272 | J11: 71598 | K11: 216422 | L11: Sustainability Awareness Drive
A12: A11 | B12: YouTube | C12: 45690 | D12: Carousel | E12: #AppleEvent #iPadPro | F12: 12136 | G12: 1117 | H12: 834 | I12: 892 | J12: 24675 | K12: 183273 | L12: Sustainability Awareness Drive
A13: A12 | B13: YouTube | C13: 45494 | D13: Tweet | E13: #MacBookAirM3 #AppleInnovation | F13: 2009 | G13: 1072 | H13: 550 | I13: 1437 | J13: 22982 | K13: 69426 | L13: iPhone 16 Launch
... A301: A300 | B301: LinkedIn | C301: 45926 | D301: Video | E301: #iPhone16Launch #AppleEvent | F301: 21216 | G301: 226 | H301: 187 | I301: 1573 | J301: 62688 | K301: 111031 | L301: Apple Event September 2025

Sheet Engagement Summary
A1: Week_Start_Date | B1: Platform | C1: New_Followers | D1: Unfollows | E1: Total_Followers | F1: Engagement_Rate | G1: Ad_Spend | H1: Campaign
A2: 45446 | B2: Instagram | C2: 4138 | D2: 361 | E2: 103777 | F2: 56.637791 | G2: 23944 | H2: ='Task 3.1'!N25 -> Health & Fitness Awareness
A3: 45446 | B3: Twitter | C3: 8693 | D3: 1261 | E3: 111209 | F3: 69.475492 | G3: 29873 | H3: ='Task 3.1'!N26 -> Health & Fitness Awareness
A4: 45446 | B4: YouTube | C4: 9264 | D4: 1141 | E4: 119332 | F4: 92.312205 | G4: 50372 | H4: ='Task 3.1'!N27 -> Sustainability Branding
A5: 45446 | B5: YouTube | C5: 8842 | D5: 971 | E5: 127203 | F5: 16.351816 | G5: 33928 | H5: ='Task 3.1'!N28 -> Sustainability Branding
A6: 45453 | B6: Instagram | C6: 7721 | D6: 506 | E6: 134418 | F6: 35.577824 | G6: 25379 | H6: ='Task 3.1'!N29 -> Health & Fitness Awareness
A7: 45453 | B7: YouTube | C7: 8002 | D7: 524 | E7: 141896 | F7: 52.064893 | G7: 46751 | H7: ='Task 3.1'!N30 -> Health & Fitness Awareness
A8: 45453 | B8: Twitter | C8: 5225 | D8: 291 | E8: 146830 | F8: 19.551863 | G8: 44546 | H8: ='Task 3.1'!N31 -> Product Launch
A9: 45453 | B9: Twitter | C9: 3978 | D9: 543 | E9: 150265 | F9: 49.159818 | G9: 34286 | H9: ='Task 3.1'!N32 -> Health & Fitness Awareness
A10: 45460 | B10: Instagram | C10: 8373 | D10: 921 | E10: 157717 | F10: 12.226329 | G10: 15110 | H10: ='Task 3.1'!N33 -> Health & Fitness Awareness
A11: 45460 | B11: Twitter | C11: 6907 | D11: 834 | E11: 163790 | F11: 54.158984 | G11: 22087 | H11: ='Task 3.1'!N34 -> Product Launch
A12: 45460 | B12: LinkedIn | C12: 7097 | D12: 369 | E12: 170518 | F12: 9.2506363 | G12: 33762 | H12: ='Task 3.1'!N35 -> Brand Engagement
A13: 45460 | B13: Instagram | C13: 6656 | D13: 978 | E13: 176196 | F13: 60.425889 | G13: 27081 | H13: ='Task 3.1'!N36 -> Brand Engagement
... A201: 45789 | B201: Twitter | C201: 8527 | D201: 1091 | E201: 1186398 | F201: 1.6760817 | G201: 41703 | H201: ='Task 3.1'!N224 -> Health & Fitness Awareness

Sheet Campaign Management
A1: Campaign_Name | B1: Start_Date | C1: End_Date | D1: Objective | E1: Ad_Spend | F1: Impressions | G1: Engagement_Uplift
A2: iPhone 16 Launch | B2: 45458 | C2: 45488 | D2: Product Launch | E2: 85000 | F2: 950000 | G2: 0.45
A3: MacBook Air M3 Campaign | B3: 45566 | C3: 45596 | D3: Product Promotion | E3: 60000 | F3: 780000 | G3: 0.38
A4: Apple Watch Ultra 2 Launch | B4: 45651 | C4: 45667 | D4: Health & Fitness Awareness | E4: 55000 | F4: 700000 | G4: 0.41
A5: Sustainability Awareness Drive | B5: 45717 | C5: 45747 | D5: Sustainability Branding | E5: 40000 | F5: 550000 | G5: 0.32
A6: Apple Event September 2025 | B6: 45901 | C6: 45930 | D6: Brand Engagement | E6: 75000 | F6: 880000 | G6: 0.47

Sheet Task 1
A1: PostID | B1: Platform | C1: Date | D1: ContentType | E1: Hashtags | F1: Likes | G1: Shares | H1: Comments | I1: Clicks | J1: Reach | K1: Impressions | L1: Campaign
A2: A1 | B2: YouTube | C2: 45649 | D2: Image | E2: #AppleWatchUltra2 | F2: 24516 | G2: 976 | H2: 974 | I2: 2675 | J2: 23275 | K2: 202932 | L2: Apple Watch Ultra 2 Launch
A3: A1 | B3: YouTube | C3: 45649 | D3: Image | E3: #HealthTech | F3: 24516 | G3: 976 | H3: 974 | I3: 2675 | J3: 23275 | K3: 202932 | L3: Apple Watch Ultra 2 Launch
A4: A2 | B4: LinkedIn | C4: 45903 | D4: Image | E4: #MacBookAirM3 | F4: 4779 | G4: 1110 | H4: 436 | I4: 1574 | J4: 77167 | K4: 71585 | L4: Apple Event September 2025
A5: A2 | B5: LinkedIn | C5: 45903 | D5: Image | E5: #AppleInnovation | F5: 4779 | G5: 1110 | H5: 436 | I5: 1574 | J5: 77167 | K5: 71585 | L5: Apple Event September 2025
A6: A3 | B6: Instagram | C6: 45789 | D6: Tweet | E6: #AppleDesign | F6: 19308 | G6: 1318 | H6: 795 | I6: 1499 | J6: 52307 | K6: 193087 | L6: Sustainability Awareness Drive
A7: A3 | B7: Instagram | C7: 45789 | D7: Tweet | E7: #Innovation | F7: 19308 | G7: 1318 | H7: 795 | I7: 1499 | J7: 52307 | K7: 193087 | L7: Sustainability Awareness Drive
A8: A4 | B8: YouTube | C8: 45516 | D8: Video | E8: #AppleEvent | F8: 3581 | G8: 517 | H8: 880 | I8: 1925 | J8: 18636 | K8: 248611 | L8: iPhone 16 Launch | O8: Approach to Task 1
A9: A4 | B9: YouTube | C9: 45516 | D9: Video | E9: #iPadPro | F9: 3581 | G9: 517 | H9: 880 | I9: 1925 | J9: 18636 | K9: 248611 | L9: iPhone 16 Launch
A10: A5 | B10: YouTube | C10: 45904 | D10: Video | E10: #AppleWatchUltra2 | F10: 21708 | G10: 435 | H10: 317 | I10: 1213 | J10: 70701 | K10: 83585 | L10: Apple Event September 2025 | N10: 1.1 | O10: Removing duplicate posts using Power Query in the 'Posts' dataset, there were no duplicates in the data.
A11: A5 | B11: YouTube | C11: 45904 | D11: Video | E11: #HealthTech | F11: 21708 | G11: 435 | H11: 317 | I11: 1213 | J11: 70701 | K11: 83585 | L11: Apple Event September 2025 | N11: 1.2 | O11: Standardized dates and platform names using Power Query, set it to 'Date' format for the entire workbook.
A12: A6 | B12: LinkedIn | C12: 45905 | D12: Image | E12: #ShotOniPhone | F12: 14677 | G12: 533 | H12: 759 | I12: 753 | J12: 23275 | K12: 66958 | L12: Apple Event September 2025 | N12: 1.3 | O12: Formatted all the numeric columns using Power Query and set them to whole numbers or decimals as needed.
A13: A7 | B13: Instagram | C13: 45467 | D13: Carousel | E13: #AppleMusic | F13: 7713 | G13: 575 | H13: 417 | I13: 336 | J13: 61660 | K13: 66017 | L13: iPhone 16 Launch | N13: 1.4 | O13: Split hashtags using space as delimiter using advanced split to rows in Power Query, split them in rows to make futher processing easier.
A14: A7 | B14: Instagram | C14: 45467 | D14: Carousel | E14: #AppleLifestyle | F14: 7713 | G14: 575 | H14: 417 | I14: 336 | J14: 61660 | K14: 66017 | L14: iPhone 16 Launch
A15: A8 | B15: Instagram | C15: 45486 | D15: Video | E15: #AppleWatch | F15: 18639 | G15: 1360 | H15: 898 | I15: 2011 | J15: 42841 | K15: 247779 | L15: iPhone 16 Launch
A16: A8 | B16: Instagram | C16: 45486 | D16: Video | E16: #Health | F16: 18639 | G16: 1360 | H16: 898 | I16: 2011 | J16: 42841 | K16: 247779 | L16: iPhone 16 Launch
A17: A9 | B17: YouTube | C17: 45534 | D17: Carousel | E17: #MacBookAirM3 | F17: 6804 | G17: 787 | H17: 970 | I17: 1095 | J17: 56343 | K17: 164677 | L17: Apple Watch Ultra 2 Launch
A18: A9 | B18: YouTube | C18: 45534 | D18: Carousel | E18: #AppleInnovation | F18: 6804 | G18: 787 | H18: 970 | I18: 1095 | J18: 56343 | K18: 164677 | L18: Apple Watch Ultra 2 Launch
A19: A10 | B19: Twitter | C19: 45727 | D19: Video | E19: #iPhone16Launch | F19: 20222 | G19: 712 | H19: 604 | I19: 1272 | J19: 71598 | K19: 216422 | L19: Sustainability Awareness Drive
A20: A10 | B20: Twitter | C20: 45727 | D20: Video | E20: #AppleEvent | F20: 20222 | G20: 712 | H20: 604 | I20: 1272 | J20: 71598 | K20: 216422 | L20: Sustainability Awareness Drive
A21: A11 | B21: YouTube | C21: 45690 | D21: Carousel | E21: #AppleEvent | F21: 12136 | G21: 1117 | H21: 834 | I21: 892 | J21: 24675 | K21: 183273 | L21: Sustainability Awareness Drive
A22: A11 | B22: YouTube | C22: 45690 | D22: Carousel | E22: #iPadPro | F22: 12136 | G22: 1117 | H22: 834 | I22: 892 | J22: 24675 | K22: 183273 | L22: Sustainability Awareness Drive
A23: A12 | B23: YouTube | C23: 45494 | D23: Tweet | E23: #MacBookAirM3 | F23: 2009 | G23: 1072 | H23: 550 | I23: 1437 | J23: 22982 | K23: 69426 | L23: iPhone 16 Launch
A24: A12 | B24: YouTube | C24: 45494 | D24: Tweet | E24: #AppleInnovation | F24: 2009 | G24: 1072 | H24: 550 | I24: 1437 | J24: 22982 | K24: 69426 | L24: iPhone 16 Launch
A25: A13 | B25: YouTube | C25: 45614 | D25: Carousel | E25: #AppleMusic | F25: 21255 | G25: 1452 | H25: 625 | I25: 1624 | J25: 21282 | K25: 57778 | L25: MacBook Air M3 Campaign
... A568: A300 | B568: LinkedIn | C568: 45926 | D568: Video | E568: #AppleEvent | F568: 21216 | G568: 226 | H568: 187 | I568: 1573 | J568: 62688 | K568: 111031 | L568: Apple Event September 2025

Sheet Task 2
A1: PostID | B1: Platform | C1: Date | D1: ContentType | E1: Hashtags | F1: Likes | G1: Shares | H1: Comments | I1: Clicks | J1: Reach | K1: Impressions | L1: Campaign | M1: Engagement Rate | R1: Average Engagement Rate per Platform | V1: Approach for Task 2.1
A2: A82 | B2: LinkedIn | C2: 45497 | D2: Video | E2: #AppleMusic #AppleLifestyle | F2: 22914 | G2: 954 | H2: 584 | I2: 1519 | J2: 13637 | K2: 49847 | L2: Apple Watch Ultra 2 Launch | M2: =(Table1_30[[#This Row],[Likes]]+Table1_30[[#This Row],[Shares]]+Table1_30[[#This Row],[Comments]])/Table1_30[[#This Row],[Impressions]] -> 0.49054106
A3: A201 | B3: YouTube | C3: 45672 | D3: Tweet | E3: #ShotOniPhone | F3: 20360 | G3: 254 | H3: 726 | I3: 1995 | J3: 14280 | K3: 43726 | L3: iPhone 16 Launch | M3: =(Table1_30[[#This Row],[Likes]]+Table1_30[[#This Row],[Shares]]+Table1_30[[#This Row],[Comments]])/Table1_30[[#This Row],[Impressions]] -> 0.48803915 | R3: Instagram | S3: =AVERAGEIF(Table1_30[Platform],R3,Table1_30[Engagement Rate]) -> 0.11777136 | V3: Calculated the engagement rates without spliting the hashtag in this one, it’s the same value both ways.
A4: A121 | B4: LinkedIn | C4: 45502 | D4: Video | E4: #AppleWatchUltra2 #HealthTech | F4: 19144 | G4: 1182 | H4: 860 | I4: 1398 | J4: 4185 | K4: 46570 | L4: Apple Watch Ultra 2 Launch | M4: =(Table1_30[[#This Row],[Likes]]+Table1_30[[#This Row],[Shares]]+Table1_30[[#This Row],[Comments]])/Table1_30[[#This Row],[Impressions]] -> 0.45492807 | R4: LinkedIn | S4: =AVERAGEIF(Table1_30[Platform],R4,Table1_30[Engagement Rate]) -> 0.12413747
A5: A127 | B5: Twitter | C5: 45684 | D5: Image | E5: #AppleEvent #iPhone16 | F5: 24415 | G5: 860 | H5: 931 | I5: 320 | J5: 65049 | K5: 62911 | L5: Apple Watch Ultra 2 Launch | M5: =(Table1_30[[#This Row],[Likes]]+Table1_30[[#This Row],[Shares]]+Table1_30[[#This Row],[Comments]])/Table1_30[[#This Row],[Impressions]] -> 0.41655672 | R5: Twitter | S5: =AVERAGEIF(Table1_30[Platform],R5,Table1_30[Engagement Rate]) -> 0.13887773
A6: A13 | B6: YouTube | C6: 45614 | D6: Carousel | E6: #AppleMusic #AppleLifestyle | F6: 21255 | G6: 1452 | H6: 625 | I6: 1624 | J6: 21282 | K6: 57778 | L6: MacBook Air M3 Campaign | M6: =(Table1_30[[#This Row],[Likes]]+Table1_30[[#This Row],[Shares]]+Table1_30[[#This Row],[Comments]])/Table1_30[[#This Row],[Impressions]] -> 0.40382152 | R6: Youtube | S6: =AVERAGEIF(Table1_30[Platform],R6,Table1_30[Engagement Rate]) -> 0.11218828
A7: A123 | B7: Twitter | C7: 45457 | D7: Video | E7: #AppleEvent #iPhone16 | F7: 17183 | G7: 1224 | H7: 943 | I7: 2010 | J7: 21481 | K7: 49110 | L7: Sustainability Awareness Drive | M7: =(Table1_30[[#This Row],[Likes]]+Table1_30[[#This Row],[Shares]]+Table1_30[[#This Row],[Comments]])/Table1_30[[#This Row],[Impressions]] -> 0.39401344
A8: A287 | B8: Instagram | C8: 45519 | D8: Video | E8: #AppleEvent #iPadPro | F8: 14977 | G8: 274 | H8: 798 | I8: 458 | J8: 6636 | K8: 43654 | L8: Apple Watch Ultra 2 Launch | M8: =(Table1_30[[#This Row],[Likes]]+Table1_30[[#This Row],[Shares]]+Table1_30[[#This Row],[Comments]])/Table1_30[[#This Row],[Impressions]] -> 0.367641
A9: A226 | B9: Twitter | C9: 45908 | D9: Tweet | E9: #AppleWatch #Health | F9: 23785 | G9: 1013 | H9: 468 | I9: 1628 | J9: 8272 | K9: 71348 | L9: Apple Event September 2025 | M9: =(Table1_30[[#This Row],[Likes]]+Table1_30[[#This Row],[Shares]]+Table1_30[[#This Row],[Comments]])/Table1_30[[#This Row],[Impressions]] -> 0.35412345 | R9: Top 10 apple post IDs with highest engagement | V9: Approach for task 2.2
A10: A231 | B10: Twitter | C10: 45909 | D10: Image | E10: #AppleMusic #AppleLifestyle | F10: 19260 | G10: 668 | H10: 994 | I10: 934 | J10: 20509 | K10: 61636 | L10: Apple Event September 2025 | M10: =(Table1_30[[#This Row],[Likes]]+Table1_30[[#This Row],[Shares]]+Table1_30[[#This Row],[Comments]])/Table1_30[[#This Row],[Impressions]] -> 0.33944448
A11: A185 | B11: Instagram | C11: 45668 | D11: Image | E11: #MacBookAirM3 #AppleInnovation | F11: 21181 | G11: 1242 | H11: 963 | I11: 1689 | J11: 49329 | K11: 69165 | L11: Apple Watch Ultra 2 Launch | M11: =(Table1_30[[#This Row],[Likes]]+Table1_30[[#This Row],[Shares]]+Table1_30[[#This Row],[Comments]])/Table1_30[[#This Row],[Impressions]] -> 0.33811899 | R11: A82 | V11: Due to calculating the engagement rates with the hashtags not split, I simply had to sort the cells from largest to smallest on the basis of their engagement rates.
A12: A106 | B12: Twitter | C12: 45692 | D12: Carousel | E12: #AppleWatch #Health | F12: 23833 | G12: 555 | H12: 523 | I12: 1330 | J12: 69141 | K12: 73997 | L12: iPhone 16 Launch | M12: =(Table1_30[[#This Row],[Likes]]+Table1_30[[#This Row],[Shares]]+Table1_30[[#This Row],[Comments]])/Table1_30[[#This Row],[Impressions]] -> 0.33664878 | R12: A201
A13: A174 | B13: LinkedIn | C13: 45465 | D13: Carousel | E13: #AppleWatchUltra2 #HealthTech | F13: 13479 | G13: 1189 | H13: 695 | I13: 416 | J13: 30229 | K13: 45704 | L13: Apple Watch Ultra 2 Launch | M13: =(Table1_30[[#This Row],[Likes]]+Table1_30[[#This Row],[Shares]]+Table1_30[[#This Row],[Comments]])/Table1_30[[#This Row],[Impressions]] -> 0.33614126 | R13: A121
A14: A254 | B14: Instagram | C14: 45671 | D14: Carousel | E14: #AppleEvent #iPhone16 | F14: 24350 | G14: 460 | H14: 666 | I14: 814 | J14: 21120 | K14: 76914 | L14: Apple Watch Ultra 2 Launch | M14: =(Table1_30[[#This Row],[Likes]]+Table1_30[[#This Row],[Shares]]+Table1_30[[#This Row],[Comments]])/Table1_30[[#This Row],[Impressions]] -> 0.33122708 | R14: A127
A15: A223 | B15: Twitter | C15: 45608 | D15: Video | E15: #AppleDesign #Innovation | F15: 17913 | G15: 1311 | H15: 859 | I15: 405 | J15: 59842 | K15: 62612 | L15: Sustainability Awareness Drive | M15: =(Table1_30[[#This Row],[Likes]]+Table1_30[[#This Row],[Shares]]+Table1_30[[#This Row],[Comments]])/Table1_30[[#This Row],[Impressions]] -> 0.32075321 | R15: A13
A16: A164 | B16: LinkedIn | C16: 45715 | D16: Image | E16: #MacBookAirM3 #AppleInnovation | F16: 16178 | G16: 1048 | H16: 871 | I16: 2553 | J16: 39025 | K16: 59508 | L16: Apple Watch Ultra 2 Launch | M16: =(Table1_30[[#This Row],[Likes]]+Table1_30[[#This Row],[Shares]]+Table1_30[[#This Row],[Comments]])/Table1_30[[#This Row],[Impressions]] -> 0.30411037 | R16: A123
A17: A151 | B17: YouTube | C17: 45499 | D17: Video | E17: #MacBookProM3 | F17: 18282 | G17: 224 | H17: 962 | I17: 890 | J17: 35105 | K17: 64089 | L17: iPhone 16 Launch | M17: =(Table1_30[[#This Row],[Likes]]+Table1_30[[#This Row],[Shares]]+Table1_30[[#This Row],[Comments]])/Table1_30[[#This Row],[Impressions]] -> 0.30376508 | R17: A287
A18: A140 | B18: Instagram | C18: 45488 | D18: Tweet | E18: #AppleMusic #AppleLifestyle | F18: 14891 | G18: 674 | H18: 521 | I18: 1091 | J18: 18101 | K18: 53669 | L18: Apple Watch Ultra 2 Launch | M18: =(Table1_30[[#This Row],[Likes]]+Table1_30[[#This Row],[Shares]]+Table1_30[[#This Row],[Comments]])/Table1_30[[#This Row],[Impressions]] -> 0.2997261 | R18: A226
A19: A83 | B19: Instagram | C19: 45580 | D19: Carousel | E19: #ShotOniPhone | F19: 17781 | G19: 993 | H19: 627 | I19: 2187 | J19: 9609 | K19: 66155 | L19: iPhone 16 Launch | M19: =(Table1_30[[#This Row],[Likes]]+Table1_30[[#This Row],[Shares]]+Table1_30[[#This Row],[Comments]])/Table1_30[[#This Row],[Impressions]] -> 0.29326582 | R19: A231
A20: A196 | B20: Twitter | C20: 45918 | D20: Tweet | E20: #MacBookProM3 | F20: 10152 | G20: 1445 | H20: 526 | I20: 513 | J20: 18959 | K20: 43712 | L20: Apple Event September 2025 | M20: =(Table1_30[[#This Row],[Likes]]+Table1_30[[#This Row],[Shares]]+Table1_30[[#This Row],[Comments]])/Table1_30[[#This Row],[Impressions]] -> 0.27733803 | R20: A185
A21: A136 | B21: Instagram | C21: 45932 | D21: Carousel | E21: #AppleDesign #Innovation | F21: 12161 | G21: 736 | H21: 876 | I21: 1233 | J21: 21337 | K21: 50225 | L21: Apple Event September 2025 | M21: =(Table1_30[[#This Row],[Likes]]+Table1_30[[#This Row],[Shares]]+Table1_30[[#This Row],[Comments]])/Table1_30[[#This Row],[Impressions]] -> 0.27422598
A22: A5 | B22: YouTube | C22: 45904 | D22: Video | E22: #AppleWatchUltra2 #HealthTech | F22: 21708 | G22: 435 | H22: 317 | I22: 1213 | J22: 70701 | K22: 83585 | L22: Apple Event September 2025 | M22: =(Table1_30[[#This Row],[Likes]]+Table1_30[[#This Row],[Shares]]+Table1_30[[#This Row],[Comments]])/Table1_30[[#This Row],[Impressions]] -> 0.2687085
A23: A80 | B23: LinkedIn | C23: 45456 | D23: Image | E23: #AppleWatchUltra2 #HealthTech | F23: 14173 | G23: 294 | H23: 257 | I23: 1288 | J23: 39466 | K23: 55563 | L23: MacBook Air M3 Campaign | M23: =(Table1_30[[#This Row],[Likes]]+Table1_30[[#This Row],[Shares]]+Table1_30[[#This Row],[Comments]])/Table1_30[[#This Row],[Impressions]] -> 0.26499649
A24: A150 | B24: LinkedIn | C24: 45526 | D24: Video | E24: #iPhonePhotography #ShotOniPhone | F24: 16124 | G24: 863 | H24: 337 | I24: 819 | J24: 85788 | K24: 68625 | L24: iPhone 16 Launch | M24: =(Table1_30[[#This Row],[Likes]]+Table1_30[[#This Row],[Shares]]+Table1_30[[#This Row],[Comments]])/Table1_30[[#This Row],[Impressions]] -> 0.25244444
A25: A220 | B25: YouTube | C25: 45445 | D25: Video | E25: #MacBookAirM3 #AppleInnovation | F25: 14199 | G25: 1206 | H25: 954 | I25: 2009 | J25: 8 | K25: 65537 | L25: Sustainability Awareness Drive | M25: =(Table1_30[[#This Row],[Likes]]+Table1_30[[#This Row],[Shares]]+Table1_30[[#This Row],[Comments]])/Table1_30[[#This Row],[Impressions]] -> 0.24961472
A26: A21 | B26: Twitter | C26: 45908 | D26: Carousel | E26: #iPhonePhotography #ShotOniPhone | F26: 22309 | G26: 773 | H26: 854 | I26: 2387 | J26: 72396 | K26: 97056 | L26: Apple Event September 2025 | M26: =(Table1_30[[#This Row],[Likes]]+Table1_30[[#This Row],[Shares]]+Table1_30[[#This Row],[Comments]])/Table1_30[[#This Row],[Impressions]] -> 0.24662051
A27: A244 | B27: Instagram | C27: 45913 | D27: Video | E27: #iPhonePhotography #ShotOniPhone | F27: 15046 | G27: 281 | H27: 515 | I27: 550 | J27: 22583 | K27: 64596 | L27: Apple Event September 2025 | M27: =(Table1_30[[#This Row],[Likes]]+Table1_30[[#This Row],[Shares]]+Table1_30[[#This Row],[Comments]])/Table1_30[[#This Row],[Impressions]] -> 0.24524738
A28: A76 | B28: Twitter | C28: 45603 | D28: Carousel | E28: #ShotOniPhone | F28: 17254 | G28: 246 | H28: 952 | I28: 871 | J28: 14957 | K28: 75946 | L28: MacBook Air M3 Campaign | M28: =(Table1_30[[#This Row],[Likes]]+Table1_30[[#This Row],[Shares]]+Table1_30[[#This Row],[Comments]])/Table1_30[[#This Row],[Impressions]] -> 0.2429621
A29: A216 | B29: Instagram | C29: 45502 | D29: Tweet | E29: #AppleWatchUltra2 #HealthTech | F29: 22590 | G29: 1462 | H29: 966 | I29: 2463 | J29: 29689 | K29: 103449 | L29: Sustainability Awareness Drive | M29: =(Table1_30[[#This Row],[Likes]]+Table1_30[[#This Row],[Shares]]+Table1_30[[#This Row],[Comments]])/Table1_30[[#This Row],[Impressions]] -> 0.24183897
A30: A51 | B30: YouTube | C30: 45456 | D30: Carousel | E30: #AppleWatch #Health | F30: 23164 | G30: 1122 | H30: 900 | I30: 888 | J30: 36938 | K30: 104674 | L30: Apple Watch Ultra 2 Launch | M30: =(Table1_30[[#This Row],[Likes]]+Table1_30[[#This Row],[Shares]]+Table1_30[[#This Row],[Comments]])/Table1_30[[#This Row],[Impressions]] -> 0.24061371
A31: A6 | B31: LinkedIn | C31: 45905 | D31: Image | E31: #ShotOniPhone | F31: 14677 | G31: 533 | H31: 759 | I31: 753 | J31: 23275 | K31: 66958 | L31: Apple Event September 2025 | M31: =(Table1_30[[#This Row],[Likes]]+Table1_30[[#This Row],[Shares]]+Table1_30[[#This Row],[Comments]])/Table1_30[[#This Row],[Impressions]] -> 0.23849279
A32: A289 | B32: Instagram | C32: 45624 | D32: Carousel | E32: #AppleMusic #AppleLifestyle | F32: 18644 | G32: 1369 | H32: 887 | I32: 1256 | J32: 43415 | K32: 88368 | L32: Sustainability Awareness Drive | M32: =(Table1_30[[#This Row],[Likes]]+Table1_30[[#This Row],[Shares]]+Table1_30[[#This Row],[Comments]])/Table1_30[[#This Row],[Impressions]] -> 0.23651095
... A301: A167 | B301: LinkedIn | C301: 45624 | D301: Carousel | E301: #AppleEvent #iPhone16 | F301: 2302 | G301: 347 | H301: 642 | I301: 2175 | J301: 56378 | K301: 198056 | L301: MacBook Air M3 Campaign | M301: =(Table1_30[[#This Row],[Likes]]+Table1_30[[#This Row],[Shares]]+Table1_30[[#This Row],[Comments]])/Table1_30[[#This Row],[Impressions]] -> 0.016616513

Sheet Task 2.3.1
D1: Pivot Table for comments, likes and shares by Content type and platform
G2: Approach for Task 2.3.1
B3: Sum of Likes | C3: Sum of Shares | D3: Sum of Comments
A4: Carousel | B4: 2251442 | C4: 155628 | D4: 101098 | F4: 1 | G4: Created a Pivot Table on the basis of our original table(preprocessed and cleaned)
A5: Instagram | B5: 494652 | C5: 30544 | D5: 24544 | F5: 2 | G5: Dragged and selected the columns Content type an Platform in rows.
A6: LinkedIn | B6: 450340 | C6: 34985 | D6: 22476 | F6: 3 | G6: Columns Likes, Shares and Comments in Values with the summation
A7: Twitter | B7: 763475 | C7: 41158 | D7: 27000
A8: YouTube | B8: 542975 | C8: 48941 | D8: 27078
A9: Image | B9: 1653566 | C9: 105415 | D9: 73110
A10: Instagram | B10: 394233 | C10: 33741 | D10: 19677
A11: LinkedIn | B11: 604302 | C11: 38355 | D11: 26447
A12: Twitter | B12: 286840 | C12: 14467 | D12: 11640
A13: YouTube | B13: 368191 | C13: 18852 | D13: 15346
A14: Tweet | B14: 1764491 | C14: 119160 | D14: 70897
A15: Instagram | B15: 409260 | C15: 28708 | D15: 17688
A16: LinkedIn | B16: 549235 | C16: 34597 | D16: 21790
A17: Twitter | B17: 469305 | C17: 29067 | D17: 16683
A18: YouTube | B18: 336691 | C18: 26788 | D18: 14736
... A24: Grand Total | B24: 7687630 | C24: 495823 | D24: 324935

Sheet Task 2.3.2
D1: Pivot Table for Average clicks per post by hashtag
A3: Row Labels | B3: Average of Clicks
A4: #iPhone16Launch | B4: 1811.3103 | D4: Approach for Task 2.3.2
A5: #Health | B5: 1711.5135
A6: #AppleWatch | B6: 1711.5135 | D6: Created a Pivot table with separated 'Hashtag' rows and clicks in values with Average
A7: #iPhonePhotography | B7: 1706.76
A8: #MacBookAirM3 | B8: 1680.3571
A9: #AppleInnovation | B9: 1680.3571
A10: #AppleWatchUltra2 | B10: 1674.96
A11: #HealthTech | B11: 1674.96
A12: #ShotOniPhone | B12: 1662.3415
A13: #AppleEvent | B13: 1639.225
A14: #AppleDesign | B14: 1592.72
A15: #Innovation | B15: 1592.72
A16: #iPhone16 | B16: 1579.4375
A17: #iPadPro | B17: 1477.2632
A18: #AppleLifestyle | B18: 1463.2941
... A23: Grand Total | B23: 1616.5838

Sheet Task 2.4
A1: PostID | B1: Platform | C1: Date | D1: ContentType | E1: Hashtags | F1: Likes | G1: Shares | H1: Comments | I1: Clicks | J1: Reach | K1: Impressions | L1: Campaign | M1: Engagement Rate
A2: A82 | B2: LinkedIn | C2: 45497 | D2: Video | E2: #AppleMusic | F2: 22914 | G2: 954 | H2: 584 | I2: 1519 | J2: 13637 | K2: 49847 | L2: Apple Watch Ultra 2 Launch | M2: 0.49054106
A3: A82 | B3: LinkedIn | C3: 45497 | D3: Video | E3: #AppleLifestyle | F3: 22914 | G3: 954 | H3: 584 | I3: 1519 | J3: 13637 | K3: 49847 | L3: Apple Watch Ultra 2 Launch | M3: 0.49054106
A4: A201 | B4: YouTube | C4: 45672 | D4: Tweet | E4: #ShotOniPhone | F4: 20360 | G4: 254 | H4: 726 | I4: 1995 | J4: 14280 | K4: 43726 | L4: iPhone 16 Launch | M4: 0.48803915
A5: A121 | B5: LinkedIn | C5: 45502 | D5: Video | E5: #AppleWatchUltra2 | F5: 19144 | G5: 1182 | H5: 860 | I5: 1398 | J5: 4185 | K5: 46570 | L5: Apple Watch Ultra 2 Launch | M5: 0.45492807
A6: A121 | B6: LinkedIn | C6: 45502 | D6: Video | E6: #HealthTech | F6: 19144 | G6: 1182 | H6: 860 | I6: 1398 | J6: 4185 | K6: 46570 | L6: Apple Watch Ultra 2 Launch | M6: 0.45492807 | P6: Hashtags | Q6: Average of Clicks
A7: A127 | B7: Twitter | C7: 45684 | D7: Image | E7: #AppleEvent | F7: 24415 | G7: 860 | H7: 931 | I7: 320 | J7: 65049 | K7: 62911 | L7: Apple Watch Ultra 2 Launch | M7: 0.41655672 | P7: #iPhone16Launch | Q7: 1811.3103
A8: A127 | B8: Twitter | C8: 45684 | D8: Image | E8: #iPhone16 | F8: 24415 | G8: 860 | H8: 931 | I8: 320 | J8: 65049 | K8: 62911 | L8: Apple Watch Ultra 2 Launch | M8: 0.41655672 | P8: #Health | Q8: 1711.5135
A9: A13 | B9: YouTube | C9: 45614 | D9: Carousel | E9: #AppleMusic | F9: 21255 | G9: 1452 | H9: 625 | I9: 1624 | J9: 21282 | K9: 57778 | L9: MacBook Air M3 Campaign | M9: 0.40382152 | P9: #AppleWatch | Q9: 1711.5135
A10: A13 | B10: YouTube | C10: 45614 | D10: Carousel | E10: #AppleLifestyle | F10: 21255 | G10: 1452 | H10: 625 | I10: 1624 | J10: 21282 | K10: 57778 | L10: MacBook Air M3 Campaign | M10: 0.40382152 | P10: #iPhonePhotography | Q10: 1706.76
A11: A123 | B11: Twitter | C11: 45457 | D11: Video | E11: #AppleEvent | F11: 17183 | G11: 1224 | H11: 943 | I11: 2010 | J11: 21481 | K11: 49110 | L11: Sustainability Awareness Drive | M11: 0.39401344 | P11: #MacBookAirM3 | Q11: 1680.3571
A12: A123 | B12: Twitter | C12: 45457 | D12: Video | E12: #iPhone16 | F12: 17183 | G12: 1224 | H12: 943 | I12: 2010 | J12: 21481 | K12: 49110 | L12: Sustainability Awareness Drive | M12: 0.39401344
A13: A287 | B13: Instagram | C13: 45519 | D13: Video | E13: #AppleEvent | F13: 14977 | G13: 274 | H13: 798 | I13: 458 | J13: 6636 | K13: 43654 | L13: Apple Watch Ultra 2 Launch | M13: 0.367641
A14: A287 | B14: Instagram | C14: 45519 | D14: Video | E14: #iPadPro | F14: 14977 | G14: 274 | H14: 798 | I14: 458 | J14: 6636 | K14: 43654 | L14: Apple Watch Ultra 2 Launch | M14: 0.367641 | P14: Approach for Task 2.4
A15: A226 | B15: Twitter | C15: 45908 | D15: Tweet | E15: #AppleWatch | F15: 23785 | G15: 1013 | H15: 468 | I15: 1628 | J15: 8272 | K15: 71348 | L15: Apple Event September 2025 | M15: 0.35412345
A16: A226 | B16: Twitter | C16: 45908 | D16: Tweet | E16: #Health | F16: 23785 | G16: 1013 | H16: 468 | I16: 1628 | J16: 8272 | K16: 71348 | L16: Apple Event September 2025 | M16: 0.35412345
A17: A231 | B17: Twitter | C17: 45909 | D17: Image | E17: #AppleMusic | F17: 19260 | G17: 668 | H17: 994 | I17: 934 | J17: 20509 | K17: 61636 | L17: Apple Event September 2025 | M17: 0.33944448 | O17: 1 | P17: On the basis of clicks on posts with related hashtags the top performing hashtags are the above hashtags.
A18: A231 | B18: Twitter | C18: 45909 | D18: Image | E18: #AppleLifestyle | F18: 19260 | G18: 668 | H18: 994 | I18: 934 | J18: 20509 | K18: 61636 | L18: Apple Event September 2025 | M18: 0.33944448 | O18: 2 | P18: Clicks is taken as a factor so that we can understand Apple's audience and engagement trends better.
A19: A185 | B19: Instagram | C19: 45668 | D19: Image | E19: #MacBookAirM3 | F19: 21181 | G19: 1242 | H19: 963 | I19: 1689 | J19: 49329 | K19: 69165 | L19: Apple Watch Ultra 2 Launch | M19: 0.33811899
A20: A185 | B20: Instagram | C20: 45668 | D20: Image | E20: #AppleInnovation | F20: 21181 | G20: 1242 | H20: 963 | I20: 1689 | J20: 49329 | K20: 69165 | L20: Apple Watch Ultra 2 Launch | M20: 0.33811899
A21: A106 | B21: Twitter | C21: 45692 | D21: Carousel | E21: #AppleWatch | F21: 23833 | G21: 555 | H21: 523 | I21: 1330 | J21: 69141 | K21: 73997 | L21: iPhone 16 Launch | M21: 0.33664878
A22: A106 | B22: Twitter | C22: 45692 | D22: Carousel | E22: #Health | F22: 23833 | G22: 555 | H22: 523 | I22: 1330 | J22: 69141 | K22: 73997 | L22: iPhone 16 Launch | M22: 0.33664878
A23: A174 | B23: LinkedIn | C23: 45465 | D23: Carousel | E23: #AppleWatchUltra2 | F23: 13479 | G23: 1189 | H23: 695 | I23: 416 | J23: 30229 | K23: 45704 | L23: Apple Watch Ultra 2 Launch | M23: 0.33614126
A24: A174 | B24: LinkedIn | C24: 45465 | D24: Carousel | E24: #HealthTech | F24: 13479 | G24: 1189 | H24: 695 | I24: 416 | J24: 30229 | K24: 45704 | L24: Apple Watch Ultra 2 Launch | M24: 0.33614126
A25: A254 | B25: Instagram | C25: 45671 | D25: Carousel | E25: #AppleEvent | F25: 24350 | G25: 460 | H25: 666 | I25: 814 | J25: 21120 | K25: 76914 | L25: Apple Watch Ultra 2 Launch | M25: 0.33122708
A26: A254 | B26: Instagram | C26: 45671 | D26: Carousel | E26: #iPhone16 | F26: 24350 | G26: 460 | H26: 666 | I26: 814 | J26: 21120 | K26: 76914 | L26: Apple Watch Ultra 2 Launch | M26: 0.33122708
A27: A223 | B27: Twitter | C27: 45608 | D27: Video | E27: #AppleDesign | F27: 17913 | G27: 1311 | H27: 859 | I27: 405 | J27: 59842 | K27: 62612 | L27: Sustainability Awareness Drive | M27: 0.32075321
A28: A223 | B28: Twitter | C28: 45608 | D28: Video | E28: #Innovation | F28: 17913 | G28: 1311 | H28: 859 | I28: 405 | J28: 59842 | K28: 62612 | L28: Sustainability Awareness Drive | M28: 0.32075321
A29: A164 | B29: LinkedIn | C29: 45715 | D29: Image | E29: #MacBookAirM3 | F29: 16178 | G29: 1048 | H29: 871 | I29: 2553 | J29: 39025 | K29: 59508 | L29: Apple Watch Ultra 2 Launch | M29: 0.30411037
A30: A164 | B30: LinkedIn | C30: 45715 | D30: Image | E30: #AppleInnovation | F30: 16178 | G30: 1048 | H30: 871 | I30: 2553 | J30: 39025 | K30: 59508 | L30: Apple Watch Ultra 2 Launch | M30: 0.30411037
... A568: A167 | B568: LinkedIn | C568: 45624 | D568: Carousel | E568: #iPhone16 | F568: 2302 | G568: 347 | H568: 642 | I568: 2175 | J568: 56378 | K568: 198056 | L568: MacBook Air M3 Campaign | M568: 0.016616513

Sheet Task 2.4.1
A3: Row Labels | B3: Average of Engagement Rate
A4: #AppleWatchUltra2 | B4: 0.14380411 | D4: Top performing hashtags based on their engagement rates
A5: #HealthTech | B5: 0.14380411
A6: #AppleLifestyle | B6: 0.13494947 | C6: 1 | D6: #AppleWatchUltra2
A7: #AppleMusic | B7: 0.13494947 | C7: 2 | D7: #HealthTech
A8: #ShotOniPhone | B8: 0.13315746 | C8: 3 | D8: #AppleLifestyle
A9: #iPhone16 | B9: 0.12600407 | C9: 4 | D9: #AppleMusic
A10: #iPhonePhotography | B10: 0.12026677 | C10: 5 | D10: #ShotOniPhone
A11: #Sustainability | B11: 0.12019462
A12: #AppleEarth | B12: 0.12019462 | D12: Approach to task 2.4
A13: #AppleEvent | B13: 0.1185215
A14: #AppleInnovation | B14: 0.1178941 | C14: 1 | D14: Created a Pivot table using Hashtags and the average of their engagement rates.
A15: #MacBookAirM3 | B15: 0.1178941 | C15: 2 | D15: Chose Engagement rates as a 'Top Performing' Factor due to Apple's business needs that stated the importance of customer loyalty and engagement with their posts.
A16: #iPhone16Launch | B16: 0.1145658 | C16: 3 | D16: The average of engagement rates gives us more insight into what type of contents and campaigns the customers find 'relatable' - another important value for Apple, to engage with.
A17: #AppleWatch | B17: 0.11399722
A18: #Health | B18: 0.11399722
A19: #iPadPro | B19: 0.11195695
A20: #AppleDesign | B20: 0.11135741
A21: #Innovation | B21: 0.11135741
A22: #MacBookProM3 | B22: 0.10955527
A23: Grand Total | B23: 0.12238019

Sheet Task 3.1
A1: PostID | B1: Platform | C1: Date | D1: ContentType | E1: Hashtags | F1: Likes | G1: Shares | H1: Comments | I1: Clicks | J1: Reach | K1: Impressions | L1: Campaign | M1: Engagement Rate | N1: Objective
A2: A82 | B2: LinkedIn | C2: 45497 | D2: Video | E2: #AppleMusic | F2: 22914 | G2: 954 | H2: 584 | I2: 1519 | J2: 13637 | K2: 49847 | L2: Apple Watch Ultra 2 Launch | M2: 0.49054106 | N2: =INDEX(Table5_2[Objective], MATCH(L2,Table5_2[Campaign_Name], 0)) -> Health & Fitness Awareness
A3: A82 | B3: LinkedIn | C3: 45497 | D3: Video | E3: #AppleLifestyle | F3: 22914 | G3: 954 | H3: 584 | I3: 1519 | J3: 13637 | K3: 49847 | L3: Apple Watch Ultra 2 Launch | M3: 0.49054106 | N3: =INDEX(Table5_2[Objective], MATCH(L3,Table5_2[Campaign_Name], 0)) -> Health & Fitness Awareness
A4: A201 | B4: YouTube | C4: 45672 | D4: Tweet | E4: #ShotOniPhone | F4: 20360 | G4: 254 | H4: 726 | I4: 1995 | J4: 14280 | K4: 43726 | L4: iPhone 16 Launch | M4: 0.48803915 | N4: =INDEX(Table5_2[Objective], MATCH(L4,Table5_2[Campaign_Name], 0)) -> Product Launch
A5: A121 | B5: LinkedIn | C5: 45502 | D5: Video | E5: #AppleWatchUltra2 | F5: 19144 | G5: 1182 | H5: 860 | I5: 1398 | J5: 4185 | K5: 46570 | L5: Apple Watch Ultra 2 Launch | M5: 0.45492807 | N5: =INDEX(Table5_2[Objective], MATCH(L5,Table5_2[Campaign_Name], 0)) -> Health & Fitness Awareness
A6: A121 | B6: LinkedIn | C6: 45502 | D6: Video | E6: #HealthTech | F6: 19144 | G6: 1182 | H6: 860 | I6: 1398 | J6: 4185 | K6: 46570 | L6: Apple Watch Ultra 2 Launch | M6: 0.45492807 | N6: =INDEX(Table5_2[Objective], MATCH(L6,Table5_2[Campaign_Name], 0)) -> Health & Fitness Awareness
A7: A127 | B7: Twitter | C7: 45684 | D7: Image | E7: #AppleEvent | F7: 24415 | G7: 860 | H7: 931 | I7: 320 | J7: 65049 | K7: 62911 | L7: Apple Watch Ultra 2 Launch | M7: 0.41655672 | N7: =INDEX(Table5_2[Objective], MATCH(L7,Table5_2[Campaign_Name], 0)) -> Health & Fitness Awareness
A8: A127 | B8: Twitter | C8: 45684 | D8: Image | E8: #iPhone16 | F8: 24415 | G8: 860 | H8: 931 | I8: 320 | J8: 65049 | K8: 62911 | L8: Apple Watch Ultra 2 Launch | M8: 0.41655672 | N8: =INDEX(Table5_2[Objective], MATCH(L8,Table5_2[Campaign_Name], 0)) -> Health & Fitness Awareness
A9: A13 | B9: YouTube | C9: 45614 | D9: Carousel | E9: #AppleMusic | F9: 21255 | G9: 1452 | H9: 625 | I9: 1624 | J9: 21282 | K9: 57778 | L9: MacBook Air M3 Campaign | M9: 0.40382152 | N9: =INDEX(Table5_2[Objective], MATCH(L9,Table5_2[Campaign_Name], 0)) -> Product Promotion | R9: Average of Engagement Rate | S9: Campaigns
A10: A13 | B10: YouTube | C10: 45614 | D10: Carousel | E10: #AppleLifestyle | F10: 21255 | G10: 1452 | H10: 625 | I10: 1624 | J10: 21282 | K10: 57778 | L10: MacBook Air M3 Campaign | M10: 0.40382152 | N10: =INDEX(Table5_2[Objective], MATCH(L10,Table5_2[Campaign_Name], 0)) -> Product Promotion | R10: Objectives | S10: Apple Event September 2025 | T10: Apple Watch Ultra 2 Launch | U10: iPhone 16 Launch | V10: MacBook Air M3 Campaign | W10: Sustainability Awareness Drive | X10: Grand Total
A11: A123 | B11: Twitter | C11: 45457 | D11: Video | E11: #AppleEvent | F11: 17183 | G11: 1224 | H11: 943 | I11: 2010 | J11: 21481 | K11: 49110 | L11: Sustainability Awareness Drive | M11: 0.39401344 | N11: =INDEX(Table5_2[Objective], MATCH(L11,Table5_2[Campaign_Name], 0)) -> Sustainability Branding | R11: Instagram | S11: 0.13695514 | T11: 0.13955403 | U11: 0.087843467 | V11: 0.096406829 | W11: 0.11599957 | X11: 0.1182887
A12: A123 | B12: Twitter | C12: 45457 | D12: Video | E12: #iPhone16 | F12: 17183 | G12: 1224 | H12: 943 | I12: 2010 | J12: 21481 | K12: 49110 | L12: Sustainability Awareness Drive | M12: 0.39401344 | N12: =INDEX(Table5_2[Objective], MATCH(L12,Table5_2[Campaign_Name], 0)) -> Sustainability Branding | R12: Health & Fitness Awareness | T12: 0.13955403 | X12: 0.13955403
A13: A287 | B13: Instagram | C13: 45519 | D13: Video | E13: #AppleEvent | F13: 14977 | G13: 274 | H13: 798 | I13: 458 | J13: 6636 | K13: 43654 | L13: Apple Watch Ultra 2 Launch | M13: 0.367641 | N13: =INDEX(Table5_2[Objective], MATCH(L13,Table5_2[Campaign_Name], 0)) -> Health & Fitness Awareness | R13: Brand Engagement | S13: 0.13695514 | X13: 0.13695514
A14: A287 | B14: Instagram | C14: 45519 | D14: Video | E14: #iPadPro | F14: 14977 | G14: 274 | H14: 798 | I14: 458 | J14: 6636 | K14: 43654 | L14: Apple Watch Ultra 2 Launch | M14: 0.367641 | N14: =INDEX(Table5_2[Objective], MATCH(L14,Table5_2[Campaign_Name], 0)) -> Health & Fitness Awareness | R14: Sustainability Branding | W14: 0.11599957 | X14: 0.11599957
A15: A226 | B15: Twitter | C15: 45908 | D15: Tweet | E15: #AppleWatch | F15: 23785 | G15: 1013 | H15: 468 | I15: 1628 | J15: 8272 | K15: 71348 | L15: Apple Event September 2025 | M15: 0.35412345 | N15: =INDEX(Table5_2[Objective], MATCH(L15,Table5_2[Campaign_Name], 0)) -> Brand Engagement | R15: Product Promotion | V15: 0.096406829 | X15: 0.096406829
A16: A226 | B16: Twitter | C16: 45908 | D16: Tweet | E16: #Health | F16: 23785 | G16: 1013 | H16: 468 | I16: 1628 | J16: 8272 | K16: 71348 | L16: Apple Event September 2025 | M16: 0.35412345 | N16: =INDEX(Table5_2[Objective], MATCH(L16,Table5_2[Campaign_Name], 0)) -> Brand Engagement | R16: Product Launch | U16: 0.087843467 | X16: 0.087843467
A17: A231 | B17: Twitter | C17: 45909 | D17: Image | E17: #AppleMusic | F17: 19260 | G17: 668 | H17: 994 | I17: 934 | J17: 20509 | K17: 61636 | L17: Apple Event September 2025 | M17: 0.33944448 | N17: =INDEX(Table5_2[Objective], MATCH(L17,Table5_2[Campaign_Name], 0)) -> Brand Engagement | R17: LinkedIn | S17: 0.11016638 | T17: 0.14660403 | U17: 0.12843165 | V17: 0.12478605 | W17: 0.10377898 | X17: 0.12495643
A18: A231 | B18: Twitter | C18: 45909 | D18: Image | E18: #AppleLifestyle | F18: 19260 | G18: 668 | H18: 994 | I18: 934 | J18: 20509 | K18: 61636 | L18: Apple Event September 2025 | M18: 0.33944448 | N18: =INDEX(Table5_2[Objective], MATCH(L18,Table5_2[Campaign_Name], 0)) -> Brand Engagement | R18: Health & Fitness Awareness | T18: 0.14660403 | X18: 0.14660403
A19: A185 | B19: Instagram | C19: 45668 | D19: Image | E19: #MacBookAirM3 | F19: 21181 | G19: 1242 | H19: 963 | I19: 1689 | J19: 49329 | K19: 69165 | L19: Apple Watch Ultra 2 Launch | M19: 0.33811899 | N19: =INDEX(Table5_2[Objective], MATCH(L19,Table5_2[Campaign_Name], 0)) -> Health & Fitness Awareness | R19: Product Launch | U19: 0.12843165 | X19: 0.12843165
A20: A185 | B20: Instagram | C20: 45668 | D20: Image | E20: #AppleInnovation | F20: 21181 | G20: 1242 | H20: 963 | I20: 1689 | J20: 49329 | K20: 69165 | L20: Apple Watch Ultra 2 Launch | M20: 0.33811899 | N20: =INDEX(Table5_2[Objective], MATCH(L20,Table5_2[Campaign_Name], 0)) -> Health & Fitness Awareness | R20: Product Promotion | V20: 0.12478605 | X20: 0.12478605
A21: A106 | B21: Twitter | C21: 45692 | D21: Carousel | E21: #AppleWatch | F21: 23833 | G21: 555 | H21: 523 | I21: 1330 | J21: 69141 | K21: 73997 | L21: iPhone 16 Launch | M21: 0.33664878 | N21: =INDEX(Table5_2[Objective], MATCH(L21,Table5_2[Campaign_Name], 0)) -> Product Launch | R21: Brand Engagement | S21: 0.11016638 | X21: 0.11016638
A22: A106 | B22: Twitter | C22: 45692 | D22: Carousel | E22: #Health | F22: 23833 | G22: 555 | H22: 523 | I22: 1330 | J22: 69141 | K22: 73997 | L22: iPhone 16 Launch | M22: 0.33664878 | N22: =INDEX(Table5_2[Objective], MATCH(L22,Table5_2[Campaign_Name], 0)) -> Product Launch | R22: Sustainability Branding | W22: 0.10377898 | X22: 0.10377898
A23: A174 | B23: LinkedIn | C23: 45465 | D23: Carousel | E23: #AppleWatchUltra2 | F23: 13479 | G23: 1189 | H23: 695 | I23: 416 | J23: 30229 | K23: 45704 | L23: Apple Watch Ultra 2 Launch | M23: 0.33614126 | N23: =INDEX(Table5_2[Objective], MATCH(L23,Table5_2[Campaign_Name], 0)) -> Health & Fitness Awareness | R23: Twitter | S23: 0.1516136 | T23: 0.14513293 | U23: 0.13738974 | V23: 0.13670377 | W23: 0.1282677 | X23: 0.13978857
A24: A174 | B24: LinkedIn | C24: 45465 | D24: Carousel | E24: #HealthTech | F24: 13479 | G24: 1189 | H24: 695 | I24: 416 | J24: 30229 | K24: 45704 | L24: Apple Watch Ultra 2 Launch | M24: 0.33614126 | N24: =INDEX(Table5_2[Objective], MATCH(L24,Table5_2[Campaign_Name], 0)) -> Health & Fitness Awareness | R24: Brand Engagement | S24: 0.1516136 | X24: 0.1516136
A25: A254 | B25: Instagram | C25: 45671 | D25: Carousel | E25: #AppleEvent | F25: 24350 | G25: 460 | H25: 666 | I25: 814 | J25: 21120 | K25: 76914 | L25: Apple Watch Ultra 2 Launch | M25: 0.33122708 | N25: =INDEX(Table5_2[Objective], MATCH(L25,Table5_2[Campaign_Name], 0)) -> Health & Fitness Awareness | R25: Health & Fitness Awareness | T25: 0.14513293 | X25: 0.14513293
A26: A254 | B26: Instagram | C26: 45671 | D26: Carousel | E26: #iPhone16 | F26: 24350 | G26: 460 | H26: 666 | I26: 814 | J26: 21120 | K26: 76914 | L26: Apple Watch Ultra 2 Launch | M26: 0.33122708 | N26: =INDEX(Table5_2[Objective], MATCH(L26,Table5_2[Campaign_Name], 0)) -> Health & Fitness Awareness | R26: Product Launch | U26: 0.13738974 | X26: 0.13738974
A27: A223 | B27: Twitter | C27: 45608 | D27: Video | E27: #AppleDesign | F27: 17913 | G27: 1311 | H27: 859 | I27: 405 | J27: 59842 | K27: 62612 | L27: Sustainability Awareness Drive | M27: 0.32075321 | N27: =INDEX(Table5_2[Objective], MATCH(L27,Table5_2[Campaign_Name], 0)) -> Sustainability Branding | R27: Product Promotion | V27: 0.13670377 | X27: 0.13670377
A28: A223 | B28: Twitter | C28: 45608 | D28: Video | E28: #Innovation | F28: 17913 | G28: 1311 | H28: 859 | I28: 405 | J28: 59842 | K28: 62612 | L28: Sustainability Awareness Drive | M28: 0.32075321 | N28: =INDEX(Table5_2[Objective], MATCH(L28,Table5_2[Campaign_Name], 0)) -> Sustainability Branding | R28: Sustainability Branding | W28: 0.1282677 | X28: 0.1282677
A29: A164 | B29: LinkedIn | C29: 45715 | D29: Image | E29: #MacBookAirM3 | F29: 16178 | G29: 1048 | H29: 871 | I29: 2553 | J29: 39025 | K29: 59508 | L29: Apple Watch Ultra 2 Launch | M29: 0.30411037 | N29: =INDEX(Table5_2[Objective], MATCH(L29,Table5_2[Campaign_Name], 0)) -> Health & Fitness Awareness | R29: YouTube | S29: 0.10449413 | T29: 0.11973748 | U29: 0.099434455 | V29: 0.11345041 | W29: 0.10497763 | X29: 0.10817234
A30: A164 | B30: LinkedIn | C30: 45715 | D30: Image | E30: #AppleInnovation | F30: 16178 | G30: 1048 | H30: 871 | I30: 2553 | J30: 39025 | K30: 59508 | L30: Apple Watch Ultra 2 Launch | M30: 0.30411037 | N30: =INDEX(Table5_2[Objective], MATCH(L30,Table5_2[Campaign_Name], 0)) -> Health & Fitness Awareness | R30: Health & Fitness Awareness | T30: 0.11973748 | X30: 0.11973748
A31: A151 | B31: YouTube | C31: 45499 | D31: Video | E31: #MacBookProM3 | F31: 18282 | G31: 224 | H31: 962 | I31: 890 | J31: 35105 | K31: 64089 | L31: iPhone 16 Launch | M31: 0.30376508 | N31: =INDEX(Table5_2[Objective], MATCH(L31,Table5_2[Campaign_Name], 0)) -> Product Launch | R31: Product Promotion | V31: 0.11345041 | X31: 0.11345041
A32: A140 | B32: Instagram | C32: 45488 | D32: Tweet | E32: #AppleMusic | F32: 14891 | G32: 674 | H32: 521 | I32: 1091 | J32: 18101 | K32: 53669 | L32: Apple Watch Ultra 2 Launch | M32: 0.2997261 | N32: =INDEX(Table5_2[Objective], MATCH(L32,Table5_2[Campaign_Name], 0)) -> Health & Fitness Awareness | R32: Sustainability Branding | W32: 0.10497763 | X32: 0.10497763
A33: A140 | B33: Instagram | C33: 45488 | D33: Tweet | E33: #AppleLifestyle | F33: 14891 | G33: 674 | H33: 521 | I33: 1091 | J33: 18101 | K33: 53669 | L33: Apple Watch Ultra 2 Launch | M33: 0.2997261 | N33: =INDEX(Table5_2[Objective], MATCH(L33,Table5_2[Campaign_Name], 0)) -> Health & Fitness Awareness | R33: Brand Engagement | S33: 0.10449413 | X33: 0.10449413
A34: A83 | B34: Instagram | C34: 45580 | D34: Carousel | E34: #ShotOniPhone | F34: 17781 | G34: 993 | H34: 627 | I34: 2187 | J34: 9609 | K34: 66155 | L34: iPhone 16 Launch | M34: 0.29326582 | N34: =INDEX(Table5_2[Objective], MATCH(L34,Table5_2[Campaign_Name], 0)) -> Product Launch | R34: Product Launch | U34: 0.099434455 | X34: 0.099434455
A35: A196 | B35: Twitter | C35: 45918 | D35: Tweet | E35: #MacBookProM3 | F35: 10152 | G35: 1445 | H35: 526 | I35: 513 | J35: 18959 | K35: 43712 | L35: Apple Event September 2025 | M35: 0.27733803 | N35: =INDEX(Table5_2[Objective], MATCH(L35,Table5_2[Campaign_Name], 0)) -> Brand Engagement | R35: Grand Total | S35: 0.12092372 | T35: 0.13868799 | U35: 0.11632445 | V35: 0.11730763 | W35: 0.11437641 | X35: 0.12238019
A36: A136 | B36: Instagram | C36: 45932 | D36: Carousel | E36: #AppleDesign | F36: 12161 | G36: 736 | H36: 876 | I36: 1233 | J36: 21337 | K36: 50225 | L36: Apple Event September 2025 | M36: 0.27422598 | N36: =INDEX(Table5_2[Objective], MATCH(L36,Table5_2[Campaign_Name], 0)) -> Brand Engagement
A37: A136 | B37: Instagram | C37: 45932 | D37: Carousel | E37: #Innovation | F37: 12161 | G37: 736 | H37: 876 | I37: 1233 | J37: 21337 | K37: 50225 | L37: Apple Event September 2025 | M37: 0.27422598 | N37: =INDEX(Table5_2[Objective], MATCH(L37,Table5_2[Campaign_Name], 0)) -> Brand Engagement
A38: A5 | B38: YouTube | C38: 45904 | D38: Video | E38: #AppleWatchUltra2 | F38: 21708 | G38: 435 | H38: 317 | I38: 1213 | J38: 70701 | K38: 83585 | L38: Apple Event September 2025 | M38: 0.2687085 | N38: =INDEX(Table5_2[Objective], MATCH(L38,Table5_2[Campaign_Name], 0)) -> Brand Engagement
A39: A5 | B39: YouTube | C39: 45904 | D39: Video | E39: #HealthTech | F39: 21708 | G39: 435 | H39: 317 | I39: 1213 | J39: 70701 | K39: 83585 | L39: Apple Event September 2025 | M39: 0.2687085 | N39: =INDEX(Table5_2[Objective], MATCH(L39,Table5_2[Campaign_Name], 0)) -> Brand Engagement
A40: A80 | B40: LinkedIn | C40: 45456 | D40: Image | E40: #AppleWatchUltra2 | F40: 14173 | G40: 294 | H40: 257 | I40: 1288 | J40: 39466 | K40: 55563 | L40: MacBook Air M3 Campaign | M40: 0.26499649 | N40: =INDEX(Table5_2[Objective], MATCH(L40,Table5_2[Campaign_Name], 0)) -> Product Promotion | R40: Platforms with Highest Engagement Rates
...

Sheet Task 3.2 & 3.4
A1: Week_Start_Date | B1: Platform | C1: New_Followers | D1: Unfollows | E1: Total_Followers | F1: Engagement_Rate | G1: Ad_Spend | H1: New followers - unfollows | I1: Growth rate
A2: 45446 | B2: Instagram | C2: 4138 | D2: 361 | E2: 103777 | F2: 56.637791 | G2: 23944 | H2: =(Table3_211[[#This Row],[New_Followers]]-Table3_211[[#This Row],[Unfollows]]) -> 3777 | I2: =Table3_211[[#This Row],[New followers - unfollows]]/(Table3_211[[#This Row],[Total_Followers]]-Table3_211[[#This Row],[New followers - unfollows]]) -> 0.03777
A3: 45446 | B3: Twitter | C3: 8693 | D3: 1261 | E3: 111209 | F3: 69.475492 | G3: 29873 | H3: =(Table3_211[[#This Row],[New_Followers]]-Table3_211[[#This Row],[Unfollows]]) -> 7432 | I3: =Table3_211[[#This Row],[New followers - unfollows]]/(Table3_211[[#This Row],[Total_Followers]]-Table3_211[[#This Row],[New followers - unfollows]]) -> 0.071615098
A4: 45446 | B4: YouTube | C4: 9264 | D4: 1141 | E4: 119332 | F4: 92.312205 | G4: 50372 | H4: =(Table3_211[[#This Row],[New_Followers]]-Table3_211[[#This Row],[Unfollows]]) -> 8123 | I4: =Table3_211[[#This Row],[New followers - unfollows]]/(Table3_211[[#This Row],[Total_Followers]]-Table3_211[[#This Row],[New followers - unfollows]]) -> 0.073042649
A5: 45446 | B5: YouTube | C5: 8842 | D5: 971 | E5: 127203 | F5: 16.351816 | G5: 33928 | H5: =(Table3_211[[#This Row],[New_Followers]]-Table3_211[[#This Row],[Unfollows]]) -> 7871 | I5: =Table3_211[[#This Row],[New followers - unfollows]]/(Table3_211[[#This Row],[Total_Followers]]-Table3_211[[#This Row],[New followers - unfollows]]) -> 0.065958838 | K5: Task 3.2 | P5: Approach for Task 3.2
A6: 45453 | B6: Instagram | C6: 7721 | D6: 506 | E6: 134418 | F6: 35.577824 | G6: 25379 | H6: =(Table3_211[[#This Row],[New_Followers]]-Table3_211[[#This Row],[Unfollows]]) -> 7215 | I6: =Table3_211[[#This Row],[New followers - unfollows]]/(Table3_211[[#This Row],[Total_Followers]]-Table3_211[[#This Row],[New followers - unfollows]]) -> 0.05672036
A7: 45453 | B7: YouTube | C7: 8002 | D7: 524 | E7: 141896 | F7: 52.064893 | G7: 46751 | H7: =(Table3_211[[#This Row],[New_Followers]]-Table3_211[[#This Row],[Unfollows]]) -> 7478 | I7: =Table3_211[[#This Row],[New followers - unfollows]]/(Table3_211[[#This Row],[Total_Followers]]-Table3_211[[#This Row],[New followers - unfollows]]) -> 0.05563243 | M7: Average of Growth rate | O7: 1 | P7: Calculated the Growth rate using the formula = New_followers - unfollows.
A8: 45453 | B8: Twitter | C8: 5225 | D8: 291 | E8: 146830 | F8: 19.551863 | G8: 44546 | H8: =(Table3_211[[#This Row],[New_Followers]]-Table3_211[[#This Row],[Unfollows]]) -> 4934 | I8: =Table3_211[[#This Row],[New followers - unfollows]]/(Table3_211[[#This Row],[Total_Followers]]-Table3_211[[#This Row],[New followers - unfollows]]) -> 0.034771946 | L8: YouTube | M8: 0.01465063 | O8: 2 | P8: Converted the Growth rate into percentage to make it understandable and standardized.
A9: 45453 | B9: Twitter | C9: 3978 | D9: 543 | E9: 150265 | F9: 49.159818 | G9: 34286 | H9: =(Table3_211[[#This Row],[New_Followers]]-Table3_211[[#This Row],[Unfollows]]) -> 3435 | I9: =Table3_211[[#This Row],[New followers - unfollows]]/(Table3_211[[#This Row],[Total_Followers]]-Table3_211[[#This Row],[New followers - unfollows]]) -> 0.023394402 | L9: Twitter | M9: 0.014133219 | O9: 3 | P9: Plotted a pivot table to display Average Growth rate across all platforms
A10: 45460 | B10: Instagram | C10: 8373 | D10: 921 | E10: 157717 | F10: 12.226329 | G10: 15110 | H10: =(Table3_211[[#This Row],[New_Followers]]-Table3_211[[#This Row],[Unfollows]]) -> 7452 | I10: =Table3_211[[#This Row],[New followers - unfollows]]/(Table3_211[[#This Row],[Total_Followers]]-Table3_211[[#This Row],[New followers - unfollows]]) -> 0.049592387 | L10: Instagram | M10: 0.012302424
A11: 45460 | B11: Twitter | C11: 6907 | D11: 834 | E11: 163790 | F11: 54.158984 | G11: 22087 | H11: =(Table3_211[[#This Row],[New_Followers]]-Table3_211[[#This Row],[Unfollows]]) -> 6073 | I11: =Table3_211[[#This Row],[New followers - unfollows]]/(Table3_211[[#This Row],[Total_Followers]]-Table3_211[[#This Row],[New followers - unfollows]]) -> 0.038505678 | L11: LinkedIn | M11: 0.0095825377
A12: 45460 | B12: LinkedIn | C12: 7097 | D12: 369 | E12: 170518 | F12: 9.2506363 | G12: 33762 | H12: =(Table3_211[[#This Row],[New_Followers]]-Table3_211[[#This Row],[Unfollows]]) -> 6728 | I12: =Table3_211[[#This Row],[New followers - unfollows]]/(Table3_211[[#This Row],[Total_Followers]]-Table3_211[[#This Row],[New followers - unfollows]]) -> 0.041076989 | L12: Grand Total | M12: 0.012520998
A13: 45460 | B13: Instagram | C13: 6656 | D13: 978 | E13: 176196 | F13: 60.425889 | G13: 27081 | H13: =(Table3_211[[#This Row],[New_Followers]]-Table3_211[[#This Row],[Unfollows]]) -> 5678 | I13: =Table3_211[[#This Row],[New followers - unfollows]]/(Table3_211[[#This Row],[Total_Followers]]-Table3_211[[#This Row],[New followers - unfollows]]) -> 0.033298537
A14: 45467 | B14: Twitter | C14: 9984 | D14: 1330 | E14: 184850 | F14: 57.524479 | G14: 44947 | H14: =(Table3_211[[#This Row],[New_Followers]]-Table3_211[[#This Row],[Unfollows]]) -> 8654 | I14: =Table3_211[[#This Row],[New followers - unfollows]]/(Table3_211[[#This Row],[Total_Followers]]-Table3_211[[#This Row],[New followers - unfollows]]) -> 0.049115757
A15: 45467 | B15: Instagram | C15: 5259 | D15: 374 | E15: 189735 | F15: 14.827523 | G15: 19596 | H15: =(Table3_211[[#This Row],[New_Followers]]-Table3_211[[#This Row],[Unfollows]]) -> 4885 | I15: =Table3_211[[#This Row],[New followers - unfollows]]/(Table3_211[[#This Row],[Total_Followers]]-Table3_211[[#This Row],[New followers - unfollows]]) -> 0.026426833
A16: 45467 | B16: YouTube | C16: 9286 | D16: 633 | E16: 198388 | F16: 5.4343005 | G16: 48019 | H16: =(Table3_211[[#This Row],[New_Followers]]-Table3_211[[#This Row],[Unfollows]]) -> 8653 | I16: =Table3_211[[#This Row],[New followers - unfollows]]/(Table3_211[[#This Row],[Total_Followers]]-Table3_211[[#This Row],[New followers - unfollows]]) -> 0.045605713 | K16: Task 3.4 | P16: Approach for Task 3.4
A17: 45467 | B17: Twitter | C17: 6901 | D17: 471 | E17: 204818 | F17: 60.827662 | G17: 52003 | H17: =(Table3_211[[#This Row],[New_Followers]]-Table3_211[[#This Row],[Unfollows]]) -> 6430 | I17: =Table3_211[[#This Row],[New followers - unfollows]]/(Table3_211[[#This Row],[Total_Followers]]-Table3_211[[#This Row],[New followers - unfollows]]) -> 0.032411235 | L17: Row Labels | M17: Average of Engagement_Rate
A18: 45474 | B18: LinkedIn | C18: 5917 | D18: 475 | E18: 210260 | F18: 17.894036 | G18: 28313 | H18: =(Table3_211[[#This Row],[New_Followers]]-Table3_211[[#This Row],[Unfollows]]) -> 5442 | I18: =Table3_211[[#This Row],[New followers - unfollows]]/(Table3_211[[#This Row],[Total_Followers]]-Table3_211[[#This Row],[New followers - unfollows]]) -> 0.02656993 | L18: YouTube | M18: 17.599263 | O18: 1 | P18: Inserted a Pivot table to compare average of engagement rates across platforms.
A19: 45474 | B19: Twitter | C19: 9429 | D19: 966 | E19: 218723 | F19: 7.6914636 | G19: 57639 | H19: =(Table3_211[[#This Row],[New_Followers]]-Table3_211[[#This Row],[Unfollows]]) -> 8463 | I19: =Table3_211[[#This Row],[New followers - unfollows]]/(Table3_211[[#This Row],[Total_Followers]]-Table3_211[[#This Row],[New followers - unfollows]]) -> 0.040250166 | L19: Twitter | M19: 17.480513 | O19: 2 | P19: Engagement rate as a defining factor as one of Apple's main objective is increasing Customer Engagement.
A20: 45474 | B20: Instagram | C20: 3530 | D20: 328 | E20: 221925 | F20: 12.83722 | G20: 11013 | H20: =(Table3_211[[#This Row],[New_Followers]]-Table3_211[[#This Row],[Unfollows]]) -> 3202 | I20: =Table3_211[[#This Row],[New followers - unfollows]]/(Table3_211[[#This Row],[Total_Followers]]-Table3_211[[#This Row],[New followers - unfollows]]) -> 0.014639521 | L20: Instagram | M20: 15.559292 | O20: 3 | P20: Along with Engagement the Growth factor across all platforms has also helped in suggesting a solution for 3.4
A21: 45474 | B21: Instagram | C21: 2960 | D21: 234 | E21: 224651 | F21: 17.412787 | G21: 59378 | H21: =(Table3_211[[#This Row],[New_Followers]]-Table3_211[[#This Row],[Unfollows]]) -> 2726 | I21: =Table3_211[[#This Row],[New followers - unfollows]]/(Table3_211[[#This Row],[Total_Followers]]-Table3_211[[#This Row],[New followers - unfollows]]) -> 0.012283429 | L21: LinkedIn | M21: 14.067998
A22: 45481 | B22: Twitter | C22: 8045 | D22: 894 | E22: 231802 | F22: 47.634188 | G22: 33705 | H22: =(Table3_211[[#This Row],[New_Followers]]-Table3_211[[#This Row],[Unfollows]]) -> 7151 | I22: =Table3_211[[#This Row],[New followers - unfollows]]/(Table3_211[[#This Row],[Total_Followers]]-Table3_211[[#This Row],[New followers - unfollows]]) -> 0.031831597 | L22: Grand Total | M22: 16.076504
A23: 45481 | B23: LinkedIn | C23: 2048 | D23: 130 | E23: 233720 | F23: 39.284614 | G23: 11828 | H23: =(Table3_211[[#This Row],[New_Followers]]-Table3_211[[#This Row],[Unfollows]]) -> 1918 | I23: =Table3_211[[#This Row],[New followers - unfollows]]/(Table3_211[[#This Row],[Total_Followers]]-Table3_211[[#This Row],[New followers - unfollows]]) -> 0.0082743031
A24: 45481 | B24: LinkedIn | C24: 6772 | D24: 536 | E24: 239956 | F24: 9.8205504 | G24: 17909 | H24: =(Table3_211[[#This Row],[New_Followers]]-Table3_211[[#This Row],[Unfollows]]) -> 6236 | I24: =Table3_211[[#This Row],[New followers - unfollows]]/(Table3_211[[#This Row],[Total_Followers]]-Table3_211[[#This Row],[New followers - unfollows]]) -> 0.026681499
A25: 45481 | B25: LinkedIn | C25: 3529 | D25: 305 | E25: 243180 | F25: 41.606629 | G25: 48356 | H25: =(Table3_211[[#This Row],[New_Followers]]-Table3_211[[#This Row],[Unfollows]]) -> 3224 | I25: =Table3_211[[#This Row],[New followers - unfollows]]/(Table3_211[[#This Row],[Total_Followers]]-Table3_211[[#This Row],[New followers - unfollows]]) -> 0.013435797
A26: 45488 | B26: Instagram | C26: 3964 | D26: 378 | E26: 246766 | F26: 13.63559 | G26: 23109 | H26: =(Table3_211[[#This Row],[New_Followers]]-Table3_211[[#This Row],[Unfollows]]) -> 3586 | I26: =Table3_211[[#This Row],[New followers - unfollows]]/(Table3_211[[#This Row],[Total_Followers]]-Table3_211[[#This Row],[New followers - unfollows]]) -> 0.014746278 | K26: Task 3.4
A27: 45488 | B27: Twitter | C27: 8137 | D27: 1045 | E27: 253858 | F27: 20.472469 | G27: 12023 | H27: =(Table3_211[[#This Row],[New_Followers]]-Table3_211[[#This Row],[Unfollows]]) -> 7092 | I27: =Table3_211[[#This Row],[New followers - unfollows]]/(Table3_211[[#This Row],[Total_Followers]]-Table3_211[[#This Row],[New followers - unfollows]]) -> 0.028739778
A28: 45488 | B28: YouTube | C28: 1963 | D28: 137 | E28: 255684 | F28: 11.208367 | G28: 24537 | H28: =(Table3_211[[#This Row],[New_Followers]]-Table3_211[[#This Row],[Unfollows]]) -> 1826 | I28: =Table3_211[[#This Row],[New followers - unfollows]]/(Table3_211[[#This Row],[Total_Followers]]-Table3_211[[#This Row],[New followers - unfollows]]) -> 0.0071929977 | K28: Advice for Apple considering the growth rates and engagement rates - continue a multiplatform
A29: 45488 | B29: Instagram | C29: 1536 | D29: 155 | E29: 257065 | F29: 12.157626 | G29: 36661 | H29: =(Table3_211[[#This Row],[New_Followers]]-Table3_211[[#This Row],[Unfollows]]) -> 1381 | I29: =Table3_211[[#This Row],[New followers - unfollows]]/(Table3_211[[#This Row],[Total_Followers]]-Table3_211[[#This Row],[New followers - unfollows]]) -> 0.0054011984 | K29: strategy, focusing more on Youtube and Twitter as they bring in high number of audience
A30: 45495 | B30: LinkedIn | C30: 8340 | D30: 911 | E30: 264494 | F30: 37.302926 | G30: 48659 | H30: =(Table3_211[[#This Row],[New_Followers]]-Table3_211[[#This Row],[Unfollows]]) -> 7429 | I30: =Table3_211[[#This Row],[New followers - unfollows]]/(Table3_211[[#This Row],[Total_Followers]]-Table3_211[[#This Row],[New followers - unfollows]]) -> 0.028899306 | K30: along with the reach and engagement.
A31: 45495 | B31: Twitter | C31: 8179 | D31: 446 | E31: 272227 | F31: 41.821715 | G31: 43848 | H31: =(Table3_211[[#This Row],[New_Followers]]-Table3_211[[#This Row],[Unfollows]]) -> 7733 | I31: =Table3_211[[#This Row],[New followers - unfollows]]/(Table3_211[[#This Row],[Total_Followers]]-Table3_211[[#This Row],[New followers - unfollows]]) -> 0.029236958
A32: 45495 | B32: LinkedIn | C32: 8967 | D32: 993 | E32: 280201 | F32: 52.792103 | G32: 47804 | H32: =(Table3_211[[#This Row],[New_Followers]]-Table3_211[[#This Row],[Unfollows]]) -> 7974 | I32: =Table3_211[[#This Row],[New followers - unfollows]]/(Table3_211[[#This Row],[Total_Followers]]-Table3_211[[#This Row],[New followers - unfollows]]) -> 0.029291731
A33: 45495 | B33: YouTube | C33: 9734 | D33: 652 | E33: 289283 | F33: 49.647923 | G33: 25379 | H33: =(Table3_211[[#This Row],[New_Followers]]-Table3_211[[#This Row],[Unfollows]]) -> 9082 | I33: =Table3_211[[#This Row],[New followers - unfollows]]/(Table3_211[[#This Row],[Total_Followers]]-Table3_211[[#This Row],[New followers - unfollows]]) -> 0.032412447
A34: 45502 | B34: LinkedIn | C34: 1845 | D34: 104 | E34: 291024 | F34: 28.158159 | G34: 37766 | H34: =(Table3_211[[#This Row],[New_Followers]]-Table3_211[[#This Row],[Unfollows]]) -> 1741 | I34: =Table3_211[[#This Row],[New followers - unfollows]]/(Table3_211[[#This Row],[Total_Followers]]-Table3_211[[#This Row],[New followers - unfollows]]) -> 0.0060183281
